[2024-02-29 20:48:41,148] {taskinstance.py:1179} INFO - Dependencies all met for <TaskInstance: ingestion_data.cargar_data scheduled__2024-02-28T20:48:30.516308+00:00 [queued]>
[2024-02-29 20:48:41,158] {taskinstance.py:1179} INFO - Dependencies all met for <TaskInstance: ingestion_data.cargar_data scheduled__2024-02-28T20:48:30.516308+00:00 [queued]>
[2024-02-29 20:48:41,159] {taskinstance.py:1376} INFO - 
--------------------------------------------------------------------------------
[2024-02-29 20:48:41,159] {taskinstance.py:1377} INFO - Starting attempt 1 of 2
[2024-02-29 20:48:41,160] {taskinstance.py:1378} INFO - 
--------------------------------------------------------------------------------
[2024-02-29 20:48:41,174] {taskinstance.py:1397} INFO - Executing <Task(PythonOperator): cargar_data> on 2024-02-28 20:48:30.516308+00:00
[2024-02-29 20:48:41,179] {standard_task_runner.py:52} INFO - Started process 609 to run task
[2024-02-29 20:48:41,181] {standard_task_runner.py:79} INFO - Running: ['***', 'tasks', 'run', 'ingestion_data', 'cargar_data', 'scheduled__2024-02-28T20:48:30.516308+00:00', '--job-id', '167', '--raw', '--subdir', 'DAGS_FOLDER/tareas.py', '--cfg-path', '/tmp/tmpzg8ivzs3', '--error-file', '/tmp/tmpl3njqfum']
[2024-02-29 20:48:41,183] {standard_task_runner.py:80} INFO - Job 167: Subtask cargar_data
[2024-02-29 20:48:41,254] {task_command.py:371} INFO - Running <TaskInstance: ingestion_data.cargar_data scheduled__2024-02-28T20:48:30.516308+00:00 [running]> on host dc73aa51ce40
[2024-02-29 20:48:41,338] {taskinstance.py:1591} INFO - Exporting the following env vars:
AIRFLOW_CTX_DAG_OWNER=***
AIRFLOW_CTX_DAG_ID=ingestion_data
AIRFLOW_CTX_TASK_ID=cargar_data
AIRFLOW_CTX_EXECUTION_DATE=2024-02-28T20:48:30.516308+00:00
AIRFLOW_CTX_TRY_NUMBER=1
AIRFLOW_CTX_DAG_RUN_ID=scheduled__2024-02-28T20:48:30.516308+00:00
[2024-02-29 20:48:41,339] {taskinstance.py:1909} ERROR - Task failed with exception
Traceback (most recent call last):
  File "/home/airflow/.local/lib/python3.7/site-packages/airflow/operators/python.py", line 171, in execute
    return_value = self.execute_callable()
  File "/home/airflow/.local/lib/python3.7/site-packages/airflow/operators/python.py", line 189, in execute_callable
    return self.python_callable(*self.op_args, **self.op_kwargs)
TypeError: cargar_datos() missing 1 required positional argument: 'df'
[2024-02-29 20:48:41,348] {taskinstance.py:1420} INFO - Marking task as UP_FOR_RETRY. dag_id=ingestion_data, task_id=cargar_data, execution_date=20240228T204830, start_date=20240229T204841, end_date=20240229T204841
[2024-02-29 20:48:41,363] {standard_task_runner.py:97} ERROR - Failed to execute job 167 for task cargar_data (cargar_datos() missing 1 required positional argument: 'df'; 609)
[2024-02-29 20:48:41,394] {local_task_job.py:156} INFO - Task exited with return code 1
[2024-02-29 20:48:41,429] {local_task_job.py:273} INFO - 0 downstream tasks scheduled from follow-on schedule check
