[2024-02-29 21:23:45,922] {taskinstance.py:1179} INFO - Dependencies all met for <TaskInstance: ingestar_data.cargar_data scheduled__2024-02-28T21:23:30.906059+00:00 [queued]>
[2024-02-29 21:23:45,930] {taskinstance.py:1179} INFO - Dependencies all met for <TaskInstance: ingestar_data.cargar_data scheduled__2024-02-28T21:23:30.906059+00:00 [queued]>
[2024-02-29 21:23:45,930] {taskinstance.py:1376} INFO - 
--------------------------------------------------------------------------------
[2024-02-29 21:23:45,932] {taskinstance.py:1377} INFO - Starting attempt 1 of 2
[2024-02-29 21:23:45,933] {taskinstance.py:1378} INFO - 
--------------------------------------------------------------------------------
[2024-02-29 21:23:45,945] {taskinstance.py:1397} INFO - Executing <Task(PythonOperator): cargar_data> on 2024-02-28 21:23:30.906059+00:00
[2024-02-29 21:23:45,949] {standard_task_runner.py:52} INFO - Started process 633 to run task
[2024-02-29 21:23:45,952] {standard_task_runner.py:79} INFO - Running: ['***', 'tasks', 'run', 'ingestar_data', 'cargar_data', 'scheduled__2024-02-28T21:23:30.906059+00:00', '--job-id', '24', '--raw', '--subdir', 'DAGS_FOLDER/tareas.py', '--cfg-path', '/tmp/tmpfejj0cka', '--error-file', '/tmp/tmpwde1g256']
[2024-02-29 21:23:45,953] {standard_task_runner.py:80} INFO - Job 24: Subtask cargar_data
[2024-02-29 21:23:46,005] {task_command.py:371} INFO - Running <TaskInstance: ingestar_data.cargar_data scheduled__2024-02-28T21:23:30.906059+00:00 [running]> on host 7b7d0ec4f6af
[2024-02-29 21:23:46,063] {taskinstance.py:1591} INFO - Exporting the following env vars:
AIRFLOW_CTX_DAG_OWNER=***
AIRFLOW_CTX_DAG_ID=ingestar_data
AIRFLOW_CTX_TASK_ID=cargar_data
AIRFLOW_CTX_EXECUTION_DATE=2024-02-28T21:23:30.906059+00:00
AIRFLOW_CTX_TRY_NUMBER=1
AIRFLOW_CTX_DAG_RUN_ID=scheduled__2024-02-28T21:23:30.906059+00:00
[2024-02-29 21:23:46,065] {taskinstance.py:1909} ERROR - Task failed with exception
Traceback (most recent call last):
  File "/home/airflow/.local/lib/python3.7/site-packages/airflow/operators/python.py", line 171, in execute
    return_value = self.execute_callable()
  File "/home/airflow/.local/lib/python3.7/site-packages/airflow/operators/python.py", line 189, in execute_callable
    return self.python_callable(*self.op_args, **self.op_kwargs)
TypeError: cargar_datos() missing 1 required positional argument: 'df'
[2024-02-29 21:23:46,073] {taskinstance.py:1420} INFO - Marking task as UP_FOR_RETRY. dag_id=ingestar_data, task_id=cargar_data, execution_date=20240228T212330, start_date=20240229T212345, end_date=20240229T212346
[2024-02-29 21:23:46,082] {standard_task_runner.py:97} ERROR - Failed to execute job 24 for task cargar_data (cargar_datos() missing 1 required positional argument: 'df'; 633)
[2024-02-29 21:23:46,125] {local_task_job.py:156} INFO - Task exited with return code 1
[2024-02-29 21:23:46,155] {local_task_job.py:273} INFO - 0 downstream tasks scheduled from follow-on schedule check
